<?xml version="1.0" ?>
<!-- Generated using onshape-to-robot -->
<!-- Onshape document_id: ac606044cb3b00c8bc5d0540 -->
<robot name="demo-robot-description">
  <!-- Link torso_assembly -->
  <link name="torso_assembly">
    <inertial>
      <origin xyz="4.91605e-18 -2.9526e-18 -4.81255e-17" rpy="0 0 0"/>
      <mass value="411.176"/>
      <inertia ixx="13.4098" ixy="0" ixz="0.0576033" iyy="18.7406" iyz="-4.43082e-16" izz="8.06749"/>
    </inertial>
    <!-- Part base -->
    <visual>
      <origin xyz="0 0 0" rpy="0 -0 0"/>
      <geometry>
        <mesh filename="assets/base.stl"/>
      </geometry>
      <material name="base_material">
        <color rgba="0.615686 0.811765 0.929412 1"/>
      </material>
    </visual>
    <collision>
      <origin xyz="0 0 0" rpy="0 -0 0"/>
      <geometry>
        <mesh filename="assets/base.stl"/>
      </geometry>
    </collision>
  </link>
  <!-- Link pelvis_assembly -->
  <link name="pelvis_assembly">
    <inertial>
      <origin xyz="-8.71637e-12 2.56959e-09 -0.113085" rpy="0 0 0"/>
      <mass value="14.426"/>
      <inertia ixx="0.0488136" ixy="-6.67368e-09" ixz="4.52216e-12" iyy="0.0730348" iyz="-4.29595e-09" izz="0.0606498"/>
    </inertial>
    <!-- Part pelvis_2 -->
    <visual>
      <origin xyz="-8.71638e-12 2.56959e-09 -0.113085" rpy="4.1926e-34 -1.08683e-34 5.79718e-19"/>
      <geometry>
        <mesh filename="assets/pelvis.stl"/>
      </geometry>
      <material name="pelvis_2_material">
        <color rgba="0.615686 0.811765 0.929412 1"/>
      </material>
    </visual>
    <collision>
      <origin xyz="-8.71638e-12 2.56959e-09 -0.113085" rpy="4.1926e-34 -1.08683e-34 5.79718e-19"/>
      <geometry>
        <mesh filename="assets/pelvis.stl"/>
      </geometry>
    </collision>
  </link>
  <!-- Frame pelvis (dummy link + fixed joint) -->
  <link name="pelvis">
    <origin xyz="0 0 0" rpy="0 -0 0"/>
    <inertial>
      <origin xyz="0 0 0" rpy="0 0 0"/>
      <mass value="1e-9"/>
      <inertia ixx="0" ixy="0" ixz="0" iyy="0" iyz="0" izz="0"/>
    </inertial>
  </link>
  <joint name="pelvis_frame" type="fixed">
    <origin xyz="2.71051e-17 -1.63816e-18 0" rpy="4.1926e-34 -1.08683e-34 5.79718e-19"/>
    <parent link="pelvis_assembly"/>
    <child link="pelvis"/>
    <axis xyz="0 0 0"/>
  </joint>
  <!-- Link l_hip_assembly -->
  <link name="l_hip_assembly">
    <inertial>
      <origin xyz="-2.84048e-10 -8.41218e-09 -0.0522607" rpy="0 0 0"/>
      <mass value="7.41924"/>
      <inertia ixx="0.0219052" ixy="6.91196e-10" ixz="5.07497e-11" iyy="0.0184985" iyz="-1.48509e-08" izz="0.0132238"/>
    </inertial>
    <!-- Part hip -->
    <visual>
      <origin xyz="-2.84048e-10 -8.41219e-09 -0.0522605" rpy="-1.5708 -1.5708 0"/>
      <geometry>
        <mesh filename="assets/hip.stl"/>
      </geometry>
      <material name="hip_material">
        <color rgba="0.615686 0.811765 0.929412 1"/>
      </material>
    </visual>
    <collision>
      <origin xyz="-2.84048e-10 -8.41219e-09 -0.0522605" rpy="-1.5708 -1.5708 0"/>
      <geometry>
        <mesh filename="assets/hip.stl"/>
      </geometry>
    </collision>
  </link>
  <!-- Frame left_hip (dummy link + fixed joint) -->
  <link name="left_hip">
    <origin xyz="0 0 0" rpy="0 -0 0"/>
    <inertial>
      <origin xyz="0 0 0" rpy="0 0 0"/>
      <mass value="1e-9"/>
      <inertia ixx="0" ixy="0" ixz="0" iyy="0" iyz="0" izz="0"/>
    </inertial>
  </link>
  <joint name="left_hip_frame" type="fixed">
    <origin xyz="2.84603e-19 0 0" rpy="-1.5708 -1.5708 0"/>
    <parent link="l_hip_assembly"/>
    <child link="left_hip"/>
    <axis xyz="0 0 0"/>
  </joint>
  <!-- Joint from pelvis_assembly to l_hip_assembly -->
  <joint name="left_hip_pitch_joint" type="revolute">
    <origin xyz="-0.123 -3.35425e-18 -0.127" rpy="1.5708 -5.83786e-16 1.5708"/>
    <parent link="pelvis_assembly"/>
    <child link="l_hip_assembly"/>
    <axis xyz="0 0 1"/>
    <limit effort="10" velocity="10" lower="-1.74533" upper="0.785398"/>
  </joint>
  <!-- Joint from torso_assembly to pelvis_assembly -->
  <joint name="waist_yaw_joint" type="revolute">
    <origin xyz="0.000624923 -1.11573e-17 -0.298822" rpy="-2.52536e-18 -4.61573e-19 0.0239641"/>
    <parent link="torso_assembly"/>
    <child link="pelvis_assembly"/>
    <axis xyz="0 0 1"/>
    <limit effort="10" velocity="10" lower="-0.809362" upper="0.761434"/>
  </joint>
</robot>
