<?xml version="1.0" ?>
<!-- Generated using onshape-to-robot -->
<!-- Onshape document_id: b077fc27aee0d6fa32aac1cf -->
<robot name="demo-robot-description">
  <!-- Link base -->
  <link name="base">
    <inertial>
      <origin xyz="0 0 0" rpy="0 0 0"/>
      <mass value="1e-09"/>
      <inertia ixx="1e-09" ixy="0" ixz="0" iyy="1e-09" iyz="0" izz="1e-09"/>
    </inertial>
    <!-- Part base -->
    <visual>
      <origin xyz="0 0 0" rpy="0 -0 0"/>
      <geometry>
        <mesh filename="assets/base.stl"/>
      </geometry>
      <material name="base_material">
        <color rgba="0.615686 0.811765 0.929412 1"/>
      </material>
    </visual>
    <collision>
      <origin xyz="0 0 0" rpy="0 -0 0"/>
      <geometry>
        <mesh filename="assets/base.stl"/>
      </geometry>
    </collision>
  </link>
  <!-- Link pelvis_2 -->
  <link name="pelvis_2">
    <inertial>
      <origin xyz="0 0 0" rpy="0 0 0"/>
      <mass value="1e-09"/>
      <inertia ixx="1e-09" ixy="0" ixz="0" iyy="1e-09" iyz="0" izz="1e-09"/>
    </inertial>
    <!-- Part pelvis_2 -->
    <visual>
      <origin xyz="3.81639e-16 1.99005e-18 -0.732" rpy="0 -0 0"/>
      <geometry>
        <mesh filename="assets/pelvis.stl"/>
      </geometry>
      <material name="pelvis_2_material">
        <color rgba="0.980392 0.713725 0.00392157 1"/>
      </material>
    </visual>
    <collision>
      <origin xyz="3.81639e-16 1.99005e-18 -0.732" rpy="0 -0 0"/>
      <geometry>
        <mesh filename="assets/pelvis.stl"/>
      </geometry>
    </collision>
  </link>
  <!-- Frame pelvis (dummy link + fixed joint) -->
  <link name="pelvis">
    <origin xyz="0 0 0" rpy="0 -0 0"/>
    <inertial>
      <origin xyz="0 0 0" rpy="0 0 0"/>
      <mass value="1e-9"/>
      <inertia ixx="0" ixy="0" ixz="0" iyy="0" iyz="0" izz="0"/>
    </inertial>
  </link>
  <joint name="pelvis_frame" type="fixed">
    <origin xyz="7.59908e-17 4.77612e-18 0" rpy="0 -0 0"/>
    <parent link="pelvis_2"/>
    <child link="pelvis"/>
    <axis xyz="0 0 0"/>
  </joint>
  <!-- Link hip -->
  <link name="hip">
    <inertial>
      <origin xyz="0 0 0" rpy="0 0 0"/>
      <mass value="1e-09"/>
      <inertia ixx="1e-09" ixy="0" ixz="0" iyy="1e-09" iyz="0" izz="1e-09"/>
    </inertial>
    <!-- Part hip -->
    <visual>
      <origin xyz="0 -0.605 0.12" rpy="-1.5708 -1.5708 0"/>
      <geometry>
        <mesh filename="assets/hip.stl"/>
      </geometry>
      <material name="hip_material">
        <color rgba="0.498039 0.498039 0.498039 1"/>
      </material>
    </visual>
    <collision>
      <origin xyz="0 -0.605 0.12" rpy="-1.5708 -1.5708 0"/>
      <geometry>
        <mesh filename="assets/hip.stl"/>
      </geometry>
    </collision>
  </link>
  <!-- Frame left_hip (dummy link + fixed joint) -->
  <link name="left_hip">
    <origin xyz="0 0 0" rpy="0 -0 0"/>
    <inertial>
      <origin xyz="0 0 0" rpy="0 0 0"/>
      <mass value="1e-9"/>
      <inertia ixx="0" ixy="0" ixz="0" iyy="0" iyz="0" izz="0"/>
    </inertial>
  </link>
  <joint name="left_hip_frame" type="fixed">
    <origin xyz="-1.53081e-19 0 -2.77556e-17" rpy="-1.5708 -1.5708 0"/>
    <parent link="hip"/>
    <child link="left_hip"/>
    <axis xyz="0 0 0"/>
  </joint>
  <!-- Joint from pelvis_2 to hip -->
  <joint name="left_hip_pitch_joint" type="revolute">
    <origin xyz="-0.12 1.99005e-18 -0.127" rpy="1.5708 -0 1.5708"/>
    <parent link="pelvis_2"/>
    <child link="hip"/>
    <axis xyz="0 0 1"/>
    <limit effort="10" velocity="10" lower="-3.141592653589793" upper="3.141592653589793"/>
  </joint>
  <!-- Joint from base to pelvis_2 -->
  <joint name="waist_yaw_joint" type="revolute">
    <origin xyz="-3.81639e-16 -1.99005e-18 0.732" rpy="0 -0 0"/>
    <parent link="base"/>
    <child link="pelvis_2"/>
    <axis xyz="0 0 1"/>
    <limit effort="10" velocity="10" lower="-3.141592653589793" upper="3.141592653589793"/>
  </joint>
</robot>
