<?xml version="1.0" ?>
<!-- Generated using onshape-to-robot -->
<!-- Onshape document_id: b077fc27aee0d6fa32aac1cf -->
<robot name="demo-robot-description">
  <!-- Link base -->
  <link name="base">
    <inertial>
      <origin xyz="-0.000624923 -5.19096e-18 1.03082" rpy="0 0 0"/>
      <mass value="411.176"/>
      <inertia ixx="13.4098" ixy="0" ixz="0.0576033" iyy="18.7406" iyz="-4.41442e-16" izz="8.06749"/>
    </inertial>
    <!-- Part base -->
    <visual>
      <origin xyz="0 0 0" rpy="0 -0 0"/>
      <geometry>
        <mesh filename="package://assets/base.stl"/>
      </geometry>
      <material name="base_material">
        <color rgba="0.615686 0.811765 0.929412 1"/>
      </material>
    </visual>
    <collision>
      <origin xyz="0 0 0" rpy="0 -0 0"/>
      <geometry>
        <mesh filename="package://assets/base.stl"/>
      </geometry>
    </collision>
  </link>
  <!-- Link pelvis_2 -->
  <link name="pelvis_2">
    <inertial>
      <origin xyz="-8.7163e-12 2.56959e-09 -0.113085" rpy="0 0 0"/>
      <mass value="14.426"/>
      <inertia ixx="0.0488136" ixy="-6.67368e-09" ixz="4.52214e-12" iyy="0.0730348" iyz="-4.29595e-09" izz="0.0606498"/>
    </inertial>
    <!-- Part pelvis_2 -->
    <visual>
      <origin xyz="3.81639e-16 1.99005e-18 -0.732" rpy="0 -0 0"/>
      <geometry>
        <mesh filename="package://assets/pelvis.stl"/>
      </geometry>
      <material name="pelvis_2_material">
        <color rgba="0.980392 0.713725 0.00392157 1"/>
      </material>
    </visual>
    <collision>
      <origin xyz="3.81639e-16 1.99005e-18 -0.732" rpy="0 -0 0"/>
      <geometry>
        <mesh filename="package://assets/pelvis.stl"/>
      </geometry>
    </collision>
  </link>
  <!-- Frame pelvis (dummy link + fixed joint) -->
  <link name="pelvis">
    <origin xyz="0 0 0" rpy="0 -0 0"/>
    <inertial>
      <origin xyz="0 0 0" rpy="0 0 0"/>
      <mass value="1e-9"/>
      <inertia ixx="0" ixy="0" ixz="0" iyy="0" iyz="0" izz="0"/>
    </inertial>
  </link>
  <joint name="pelvis_frame" type="fixed">
    <origin xyz="7.59908e-17 4.77612e-18 0" rpy="0 -0 0"/>
    <parent link="pelvis_2"/>
    <child link="pelvis"/>
    <axis xyz="0 0 0"/>
  </joint>
  <!-- Link hip -->
  <link name="hip">
    <inertial>
      <origin xyz="-2.84048e-10 -8.41218e-09 -0.0522607" rpy="0 0 0"/>
      <mass value="7.41924"/>
      <inertia ixx="0.0219052" ixy="6.91196e-10" ixz="5.07497e-11" iyy="0.0184985" iyz="-1.48509e-08" izz="0.0132238"/>
    </inertial>
    <!-- Part hip -->
    <visual>
      <origin xyz="0 -0.605 0.12" rpy="-1.5708 -1.5708 0"/>
      <geometry>
        <mesh filename="package://assets/hip.stl"/>
      </geometry>
      <material name="hip_material">
        <color rgba="0.498039 0.498039 0.498039 1"/>
      </material>
    </visual>
    <collision>
      <origin xyz="0 -0.605 0.12" rpy="-1.5708 -1.5708 0"/>
      <geometry>
        <mesh filename="package://assets/hip.stl"/>
      </geometry>
    </collision>
  </link>
  <!-- Frame left_hip (dummy link + fixed joint) -->
  <link name="left_hip">
    <origin xyz="0 0 0" rpy="0 -0 0"/>
    <inertial>
      <origin xyz="0 0 0" rpy="0 0 0"/>
      <mass value="1e-9"/>
      <inertia ixx="0" ixy="0" ixz="0" iyy="0" iyz="0" izz="0"/>
    </inertial>
  </link>
  <joint name="left_hip_frame" type="fixed">
    <origin xyz="-1.53081e-19 0 -2.77556e-17" rpy="-1.5708 -1.5708 0"/>
    <parent link="hip"/>
    <child link="left_hip"/>
    <axis xyz="0 0 0"/>
  </joint>
  <!-- Joint from pelvis_2 to hip -->
  <joint name="left_hip_pitch_joint" type="revolute">
    <origin xyz="-0.12 1.99005e-18 -0.127" rpy="1.5708 -0 1.5708"/>
    <parent link="pelvis_2"/>
    <child link="hip"/>
    <axis xyz="0 0 1"/>
    <limit effort="10" velocity="10" lower="-3.141592653589793" upper="3.141592653589793"/>
  </joint>
  <!-- Joint from base to pelvis_2 -->
  <joint name="waist_yaw_joint" type="revolute">
    <origin xyz="-3.81639e-16 -1.99005e-18 0.732" rpy="0 -0 0"/>
    <parent link="base"/>
    <child link="pelvis_2"/>
    <axis xyz="0 0 1"/>
    <limit effort="10" velocity="10" lower="-3.141592653589793" upper="3.141592653589793"/>
  </joint>
</robot>
