<?xml version="1.0" ?>
<!-- Generated using onshape-to-robot -->
<!-- Onshape document_id: 0d8fb7f5563559787c5a3429 -->
<robot name="demo-robot-description">
  <!-- Link base -->
  <link name="base">
    <inertial>
      <origin xyz="-6.56912e-18 5.85996e-18 -2.05434e-16" rpy="0 0 0"/>
      <mass value="56.7343"/>
      <inertia ixx="1.73041" ixy="5.39356e-06" ixz="0.00806991" iyy="2.29063" iyz="0.000951521" izz="0.937382"/>
    </inertial>
    <!-- Part base -->
    <visual>
      <origin xyz="0 0 0" rpy="0 -0 0"/>
      <geometry>
        <mesh filename="assets/base.stl"/>
      </geometry>
      <material name="base_material">
        <color rgba="0.615686 0.811765 0.929412 1"/>
      </material>
    </visual>
    <collision>
      <origin xyz="0 0 0" rpy="0 -0 0"/>
      <geometry>
        <mesh filename="assets/base.stl"/>
      </geometry>
    </collision>
  </link>
  <!-- Link pelvis_assembly -->
  <link name="pelvis_assembly">
    <inertial>
      <origin xyz="-1.15585e-11 2.83846e-09 -0.108531" rpy="0 0 0"/>
      <mass value="1.73229"/>
      <inertia ixx="0.00661031" ixy="-1.15089e-09" ixz="6.28883e-13" iyy="0.00816889" iyz="-5.47587e-10" izz="0.00634147"/>
    </inertial>
    <!-- Part frame -->
    <visual>
      <origin xyz="4.11997e-17 5.69206e-19 0" rpy="1.18446e-17 -9.50293e-17 1.81448e-32"/>
      <geometry>
        <mesh filename="assets/frame.stl"/>
      </geometry>
      <material name="frame_material">
        <color rgba="0.917647 0.917647 0.917647 1"/>
      </material>
    </visual>
    <collision>
      <origin xyz="4.11997e-17 5.69206e-19 0" rpy="1.18446e-17 -9.50293e-17 1.81448e-32"/>
      <geometry>
        <mesh filename="assets/frame.stl"/>
      </geometry>
    </collision>
    <!-- Part frame_2 -->
    <visual>
      <origin xyz="0.1 -1.14383e-17 -0.127" rpy="-1.22548e-16 -2.83036e-16 2.10001e-32"/>
      <geometry>
        <mesh filename="assets/frame.stl"/>
      </geometry>
      <material name="frame_2_material">
        <color rgba="0.917647 0.917647 0.917647 1"/>
      </material>
    </visual>
    <collision>
      <origin xyz="0.1 -1.14383e-17 -0.127" rpy="-1.22548e-16 -2.83036e-16 2.10001e-32"/>
      <geometry>
        <mesh filename="assets/frame.stl"/>
      </geometry>
    </collision>
    <!-- Part pelvis -->
    <visual>
      <origin xyz="-1.15585e-11 2.94601e-10 -0.108531" rpy="0 -0 1.50404e-49"/>
      <geometry>
        <mesh filename="assets/pelvis.stl"/>
      </geometry>
      <material name="pelvis_material">
        <color rgba="0.615686 0.811765 0.929412 1"/>
      </material>
    </visual>
    <collision>
      <origin xyz="-1.15585e-11 2.94601e-10 -0.108531" rpy="0 -0 1.50404e-49"/>
      <geometry>
        <mesh filename="assets/pelvis.stl"/>
      </geometry>
    </collision>
  </link>
  <!-- Link l_hip_assembly -->
  <link name="l_hip_assembly">
    <inertial>
      <origin xyz="-9.889e-10 -7.90235e-09 -0.0502172" rpy="0 0 0"/>
      <mass value="1.00754"/>
      <inertia ixx="0.00307921" ixy="-7.84672e-10" ixz="-1.53877e-10" iyy="0.00246671" iyz="-2.2706e-09" izz="0.00182549"/>
    </inertial>
    <!-- Part frame_3 -->
    <visual>
      <origin xyz="-1.81333e-17 0 -2.08167e-16" rpy="-1.5708 -1.5708 0"/>
      <geometry>
        <mesh filename="assets/frame.stl"/>
      </geometry>
      <material name="frame_3_material">
        <color rgba="0.917647 0.917647 0.917647 1"/>
      </material>
    </visual>
    <collision>
      <origin xyz="-1.81333e-17 0 -2.08167e-16" rpy="-1.5708 -1.5708 0"/>
      <geometry>
        <mesh filename="assets/frame.stl"/>
      </geometry>
    </collision>
    <!-- Part l_hip -->
    <visual>
      <origin xyz="-9.88905e-10 -7.9024e-09 -0.0502166" rpy="-1.5708 -1.5708 0"/>
      <geometry>
        <mesh filename="assets/l_hip.stl"/>
      </geometry>
      <material name="l_hip_material">
        <color rgba="0.615686 0.811765 0.929412 1"/>
      </material>
    </visual>
    <collision>
      <origin xyz="-9.88905e-10 -7.9024e-09 -0.0502166" rpy="-1.5708 -1.5708 0"/>
      <geometry>
        <mesh filename="assets/l_hip.stl"/>
      </geometry>
    </collision>
  </link>
  <!-- Link l_upper_femur_assembly -->
  <link name="l_upper_femur_assembly">
    <inertial>
      <origin xyz="5.72081e-07 -0.0707393 0.0191109" rpy="0 0 0"/>
      <mass value="0.515655"/>
      <inertia ixx="0.00215582" ixy="-9.06188e-09" ixz="1.57882e-08" iyy="0.00126845" iyz="0.000509998" izz="0.00199223"/>
    </inertial>
    <!-- Part frame_4 -->
    <visual>
      <origin xyz="0 0 6.93889e-18" rpy="-1.5708 8.05391e-30 3.61568e-16"/>
      <geometry>
        <mesh filename="assets/frame.stl"/>
      </geometry>
      <material name="frame_4_material">
        <color rgba="0.917647 0.917647 0.917647 1"/>
      </material>
    </visual>
    <collision>
      <origin xyz="0 0 6.93889e-18" rpy="-1.5708 8.05391e-30 3.61568e-16"/>
      <geometry>
        <mesh filename="assets/frame.stl"/>
      </geometry>
    </collision>
    <!-- Part l_upper_femur -->
    <visual>
      <origin xyz="4.44645e-08 -0.0707395 0.0191113" rpy="-1.5708 -4.622e-33 0"/>
      <geometry>
        <mesh filename="assets/l_upper_femur.stl"/>
      </geometry>
      <material name="l_upper_femur_material">
        <color rgba="0.615686 0.811765 0.929412 1"/>
      </material>
    </visual>
    <collision>
      <origin xyz="4.44645e-08 -0.0707395 0.0191113" rpy="-1.5708 -4.622e-33 0"/>
      <geometry>
        <mesh filename="assets/l_upper_femur.stl"/>
      </geometry>
    </collision>
  </link>
  <!-- Link l_lower_femur_assembly -->
  <link name="l_lower_femur_assembly">
    <inertial>
      <origin xyz="2.7904e-09 -4.11691e-09 -0.0911492" rpy="0 0 0"/>
      <mass value="2.28451"/>
      <inertia ixx="0.0097292" ixy="-3.03995e-09" ixz="4.28149e-10" iyy="0.00940931" iyz="-5.23547e-10" izz="0.00389334"/>
    </inertial>
    <!-- Part frame_5 -->
    <visual>
      <origin xyz="0 2.73761e-18 -2.22045e-16" rpy="-2.74143e-15 -9.29624e-16 -1.4988e-15"/>
      <geometry>
        <mesh filename="assets/frame.stl"/>
      </geometry>
      <material name="frame_5_material">
        <color rgba="0.917647 0.917647 0.917647 1"/>
      </material>
    </visual>
    <collision>
      <origin xyz="0 2.73761e-18 -2.22045e-16" rpy="-2.74143e-15 -9.29624e-16 -1.4988e-15"/>
      <geometry>
        <mesh filename="assets/frame.stl"/>
      </geometry>
    </collision>
    <!-- Part l_lower_femur -->
    <visual>
      <origin xyz="-5.8244e-10 -3.97077e-09 -0.0911491" rpy="-4.4147e-33 -1.64914e-32 4.86428e-32"/>
      <geometry>
        <mesh filename="assets/l_lower_femur.stl"/>
      </geometry>
      <material name="l_lower_femur_material">
        <color rgba="0.615686 0.811765 0.929412 1"/>
      </material>
    </visual>
    <collision>
      <origin xyz="-5.8244e-10 -3.97077e-09 -0.0911491" rpy="-4.4147e-33 -1.64914e-32 4.86428e-32"/>
      <geometry>
        <mesh filename="assets/l_lower_femur.stl"/>
      </geometry>
    </collision>
  </link>
  <!-- Link l_tibia_assembly -->
  <link name="l_tibia_assembly">
    <inertial>
      <origin xyz="-0.0016245 -0.165661 0.0212839" rpy="0 0 0"/>
      <mass value="1.97391"/>
      <inertia ixx="0.0186447" ixy="-0.000186353" ixz="1.19555e-05" iyy="0.00232119" iyz="0.00101771" izz="0.0184056"/>
    </inertial>
    <!-- Part frame_6 -->
    <visual>
      <origin xyz="0 0 5.55112e-17" rpy="-1.5708 -1.5708 0"/>
      <geometry>
        <mesh filename="assets/frame.stl"/>
      </geometry>
      <material name="frame_6_material">
        <color rgba="0.917647 0.917647 0.917647 1"/>
      </material>
    </visual>
    <collision>
      <origin xyz="0 0 5.55112e-17" rpy="-1.5708 -1.5708 0"/>
      <geometry>
        <mesh filename="assets/frame.stl"/>
      </geometry>
    </collision>
    <!-- Part l_tibia -->
    <visual>
      <origin xyz="-0.00162454 -0.165662 0.0212841" rpy="-1.5708 -1.5708 0"/>
      <geometry>
        <mesh filename="assets/l_tibia.stl"/>
      </geometry>
      <material name="l_tibia_material">
        <color rgba="0.615686 0.811765 0.929412 1"/>
      </material>
    </visual>
    <collision>
      <origin xyz="-0.00162454 -0.165662 0.0212841" rpy="-1.5708 -1.5708 0"/>
      <geometry>
        <mesh filename="assets/l_tibia.stl"/>
      </geometry>
    </collision>
  </link>
  <!-- Link l_ankle_assembly -->
  <link name="l_ankle_assembly">
    <inertial>
      <origin xyz="0.00100905 -0.00935595 -0.004" rpy="0 0 0"/>
      <mass value="0.00435879"/>
      <inertia ixx="2.3825e-07" ixy="2.48238e-08" ixz="3.54204e-38" iyy="2.93561e-07" iyz="1.2075e-39" izz="4.89925e-07"/>
    </inertial>
    <!-- Part frame_7 -->
    <visual>
      <origin xyz="-2.84061e-17 -2.22045e-16 5.55112e-17" rpy="-1.5708 -1.5708 0"/>
      <geometry>
        <mesh filename="assets/frame.stl"/>
      </geometry>
      <material name="frame_7_material">
        <color rgba="0.917647 0.917647 0.917647 1"/>
      </material>
    </visual>
    <collision>
      <origin xyz="-2.84061e-17 -2.22045e-16 5.55112e-17" rpy="-1.5708 -1.5708 0"/>
      <geometry>
        <mesh filename="assets/frame.stl"/>
      </geometry>
    </collision>
    <!-- Part l_ankle -->
    <visual>
      <origin xyz="0.00100905 -0.00935595 -0.004" rpy="-1.5708 -1.5708 0"/>
      <geometry>
        <mesh filename="assets/l_ankle.stl"/>
      </geometry>
      <material name="l_ankle_material">
        <color rgba="0.615686 0.811765 0.929412 1"/>
      </material>
    </visual>
    <collision>
      <origin xyz="0.00100905 -0.00935595 -0.004" rpy="-1.5708 -1.5708 0"/>
      <geometry>
        <mesh filename="assets/l_ankle.stl"/>
      </geometry>
    </collision>
  </link>
  <!-- Link l_foot_assembly -->
  <link name="l_foot_assembly">
    <inertial>
      <origin xyz="-2.1647e-07 0.0064986 -0.00996008" rpy="0 0 0"/>
      <mass value="0.282308"/>
      <inertia ixx="0.000678573" ixy="1.86655e-10" ixz="-3.27534e-09" iyy="0.000739455" iyz="-2.40954e-05" izz="0.000104866"/>
    </inertial>
    <!-- Part frame_8 -->
    <visual>
      <origin xyz="0 0 -0.01" rpy="1.5708 2.25763e-28 -8.38559e-28"/>
      <geometry>
        <mesh filename="assets/frame.stl"/>
      </geometry>
      <material name="frame_8_material">
        <color rgba="0.917647 0.917647 0.917647 1"/>
      </material>
    </visual>
    <collision>
      <origin xyz="0 0 -0.01" rpy="1.5708 2.25763e-28 -8.38559e-28"/>
      <geometry>
        <mesh filename="assets/frame.stl"/>
      </geometry>
    </collision>
    <!-- Part l_foot -->
    <visual>
      <origin xyz="-1.154e-08 0.0064987 -0.00995996" rpy="1.5708 -4.86428e-32 0"/>
      <geometry>
        <mesh filename="assets/l_foot.stl"/>
      </geometry>
      <material name="l_foot_material">
        <color rgba="0.615686 0.811765 0.929412 1"/>
      </material>
    </visual>
    <collision>
      <origin xyz="-1.154e-08 0.0064987 -0.00995996" rpy="1.5708 -4.86428e-32 0"/>
      <geometry>
        <mesh filename="assets/l_foot.stl"/>
      </geometry>
    </collision>
  </link>
  <!-- Joint from l_ankle_assembly to l_foot_assembly -->
  <joint name="left_ankle_roll_joint" type="revolute">
    <origin xyz="0.0195 -0.015 -0.004" rpy="3.14159 -1.5708 0"/>
    <parent link="l_ankle_assembly"/>
    <child link="l_foot_assembly"/>
    <axis xyz="0 0 1"/>
    <limit effort="10" velocity="10" lower="-0.349066" upper="0.349066"/>
  </joint>
  <!-- Joint from l_tibia_assembly to l_ankle_assembly -->
  <joint name="left_ankle_pitch_joint" type="revolute">
    <origin xyz="0.0015 -0.38 0.0291" rpy="2.44547e-29 1.0601e-29 3.67609e-28"/>
    <parent link="l_tibia_assembly"/>
    <child link="l_ankle_assembly"/>
    <axis xyz="0 0 1"/>
    <limit effort="10" velocity="10" lower="-0.523599" upper="0.785398"/>
  </joint>
  <!-- Joint from l_lower_femur_assembly to l_tibia_assembly -->
  <joint name="left_knee_joint" type="revolute">
    <origin xyz="-0.025 1.45825e-17 -0.203" rpy="1.5708 -1.17888e-30 1.5708"/>
    <parent link="l_lower_femur_assembly"/>
    <child link="l_tibia_assembly"/>
    <axis xyz="0 0 1"/>
    <limit effort="10" velocity="10" lower="-2.35619" upper="0.174533"/>
  </joint>
  <!-- Joint from l_upper_femur_assembly to l_lower_femur_assembly -->
  <joint name="left_hip_yaw_joint" type="revolute">
    <origin xyz="1.94289e-16 -0.145 0.035" rpy="-1.5708 1.60891e-31 4.19992e-16"/>
    <parent link="l_upper_femur_assembly"/>
    <child link="l_lower_femur_assembly"/>
    <axis xyz="0 0 1"/>
    <limit effort="10" velocity="10" lower="-1.5708" upper="1.5708"/>
  </joint>
  <!-- Joint from l_hip_assembly to l_upper_femur_assembly -->
  <joint name="left_hip_roll_joint" type="revolute">
    <origin xyz="0.035 1.11022e-16 -0.1" rpy="5.29418e-16 -1.5708 0"/>
    <parent link="l_hip_assembly"/>
    <child link="l_upper_femur_assembly"/>
    <axis xyz="0 0 1"/>
    <limit effort="10" velocity="10" lower="-1.5708" upper="0.523599"/>
  </joint>
  <!-- Joint from pelvis_assembly to l_hip_assembly -->
  <joint name="left_hip_pitch_joint" type="revolute">
    <origin xyz="-0.103 2.79724e-17 -0.127" rpy="1.5708 6.66134e-16 1.5708"/>
    <parent link="pelvis_assembly"/>
    <child link="l_hip_assembly"/>
    <axis xyz="0 0 1"/>
    <limit effort="10" velocity="10" lower="-1.5708" upper="2.53073"/>
  </joint>
  <!-- Link r_hip_assembly -->
  <link name="r_hip_assembly">
    <inertial>
      <origin xyz="-9.88897e-10 7.90233e-09 -0.0502172" rpy="0 0 0"/>
      <mass value="1.00754"/>
      <inertia ixx="0.00307921" ixy="9.1627e-10" ixz="-1.53877e-10" iyy="0.00246671" iyz="2.2706e-09" izz="0.00182549"/>
    </inertial>
    <!-- Part r_hip -->
    <visual>
      <origin xyz="-9.88905e-10 7.9024e-09 -0.0502166" rpy="1.5708 1.5708 0"/>
      <geometry>
        <mesh filename="assets/r_hip.stl"/>
      </geometry>
      <material name="r_hip_material">
        <color rgba="0.615686 0.811765 0.929412 1"/>
      </material>
    </visual>
    <collision>
      <origin xyz="-9.88905e-10 7.9024e-09 -0.0502166" rpy="1.5708 1.5708 0"/>
      <geometry>
        <mesh filename="assets/r_hip.stl"/>
      </geometry>
    </collision>
  </link>
  <!-- Link r_upper_femur_assemby -->
  <link name="r_upper_femur_assemby">
    <inertial>
      <origin xyz="-4.97967e-07 -0.0707397 0.0191111" rpy="0 0 0"/>
      <mass value="0.515653"/>
      <inertia ixx="0.0021558" ixy="9.33794e-09" ixz="-1.50007e-08" iyy="0.00126846" iyz="0.000509989" izz="0.00199222"/>
    </inertial>
    <!-- Part frame_9 -->
    <visual>
      <origin xyz="2.77556e-17 0 1.8735e-16" rpy="-1.5708 2.9897e-29 2.38024e-16"/>
      <geometry>
        <mesh filename="assets/frame.stl"/>
      </geometry>
      <material name="frame_9_material">
        <color rgba="0.917647 0.917647 0.917647 1"/>
      </material>
    </visual>
    <collision>
      <origin xyz="2.77556e-17 0 1.8735e-16" rpy="-1.5708 2.9897e-29 2.38024e-16"/>
      <geometry>
        <mesh filename="assets/frame.stl"/>
      </geometry>
    </collision>
    <!-- Part r_upper_femur -->
    <visual>
      <origin xyz="-4.78821e-08 -0.0707395 0.0191113" rpy="-1.5708 -6.37021e-45 0"/>
      <geometry>
        <mesh filename="assets/r_upper_femur.stl"/>
      </geometry>
      <material name="r_upper_femur_material">
        <color rgba="0.615686 0.811765 0.929412 1"/>
      </material>
    </visual>
    <collision>
      <origin xyz="-4.78821e-08 -0.0707395 0.0191113" rpy="-1.5708 -6.37021e-45 0"/>
      <geometry>
        <mesh filename="assets/r_upper_femur.stl"/>
      </geometry>
    </collision>
  </link>
  <!-- Link r_lower_femur_assembly -->
  <link name="r_lower_femur_assembly">
    <inertial>
      <origin xyz="8.74682e-09 -1.97647e-08 -0.0911492" rpy="0 0 0"/>
      <mass value="2.28451"/>
      <inertia ixx="0.00972919" ixy="2.67631e-09" ixz="1.2769e-09" iyy="0.00940931" iyz="-2.58595e-09" izz="0.00389334"/>
    </inertial>
    <!-- Part frame_10 -->
    <visual>
      <origin xyz="0 5.17707e-18 1.11022e-16" rpy="-3.00455e-16 -3.44055e-16 1.06246e-30"/>
      <geometry>
        <mesh filename="assets/frame.stl"/>
      </geometry>
      <material name="frame_10_material">
        <color rgba="0.917647 0.917647 0.917647 1"/>
      </material>
    </visual>
    <collision>
      <origin xyz="0 5.17707e-18 1.11022e-16" rpy="-3.00455e-16 -3.44055e-16 1.06246e-30"/>
      <geometry>
        <mesh filename="assets/frame.stl"/>
      </geometry>
    </collision>
    <!-- Part r_lower_femur -->
    <visual>
      <origin xyz="5.81823e-09 -4.29417e-09 -0.0911491" rpy="0 -0 1.21643e-45"/>
      <geometry>
        <mesh filename="assets/r_lower_femur.stl"/>
      </geometry>
      <material name="r_lower_femur_material">
        <color rgba="0.615686 0.811765 0.929412 1"/>
      </material>
    </visual>
    <collision>
      <origin xyz="5.81823e-09 -4.29417e-09 -0.0911491" rpy="0 -0 1.21643e-45"/>
      <geometry>
        <mesh filename="assets/r_lower_femur.stl"/>
      </geometry>
    </collision>
  </link>
  <!-- Link r_tibia_assembly -->
  <link name="r_tibia_assembly">
    <inertial>
      <origin xyz="-0.00162429 0.165662 0.0212835" rpy="0 0 0"/>
      <mass value="1.97394"/>
      <inertia ixx="0.0186448" ixy="0.000186267" ixz="1.1983e-05" iyy="0.0023212" iyz="-0.00101763" izz="0.0184057"/>
    </inertial>
    <!-- Part frame_11 -->
    <visual>
      <origin xyz="-4.58618e-17 -1.11022e-16 4.996e-16" rpy="1.5708 1.5708 0"/>
      <geometry>
        <mesh filename="assets/frame.stl"/>
      </geometry>
      <material name="frame_11_material">
        <color rgba="0.917647 0.917647 0.917647 1"/>
      </material>
    </visual>
    <collision>
      <origin xyz="-4.58618e-17 -1.11022e-16 4.996e-16" rpy="1.5708 1.5708 0"/>
      <geometry>
        <mesh filename="assets/frame.stl"/>
      </geometry>
    </collision>
    <!-- Part r_tibia -->
    <visual>
      <origin xyz="-0.00162455 0.165662 0.0212841" rpy="1.5708 1.5708 0"/>
      <geometry>
        <mesh filename="assets/r_tibia.stl"/>
      </geometry>
      <material name="r_tibia_material">
        <color rgba="0.615686 0.811765 0.929412 1"/>
      </material>
    </visual>
    <collision>
      <origin xyz="-0.00162455 0.165662 0.0212841" rpy="1.5708 1.5708 0"/>
      <geometry>
        <mesh filename="assets/r_tibia.stl"/>
      </geometry>
    </collision>
  </link>
  <!-- Link l_ankle_assembly_2 -->
  <link name="l_ankle_assembly_2">
    <inertial>
      <origin xyz="0.00100905 0.00935595 -0.004" rpy="0 0 0"/>
      <mass value="0.00435879"/>
      <inertia ixx="2.3825e-07" ixy="-2.48238e-08" ixz="-3.22987e-51" iyy="2.93561e-07" iyz="9.94019e-53" izz="4.89925e-07"/>
    </inertial>
    <!-- Part frame_12 -->
    <visual>
      <origin xyz="3.68629e-18 0 -8.32667e-17" rpy="1.5708 1.5708 0"/>
      <geometry>
        <mesh filename="assets/frame.stl"/>
      </geometry>
      <material name="frame_12_material">
        <color rgba="0.917647 0.917647 0.917647 1"/>
      </material>
    </visual>
    <collision>
      <origin xyz="3.68629e-18 0 -8.32667e-17" rpy="1.5708 1.5708 0"/>
      <geometry>
        <mesh filename="assets/frame.stl"/>
      </geometry>
    </collision>
    <!-- Part l_ankle_2 -->
    <visual>
      <origin xyz="0.00100905 0.00935595 -0.004" rpy="1.5708 1.5708 0"/>
      <geometry>
        <mesh filename="assets/l_ankle.stl"/>
      </geometry>
      <material name="l_ankle_2_material">
        <color rgba="0.615686 0.811765 0.929412 1"/>
      </material>
    </visual>
    <collision>
      <origin xyz="0.00100905 0.00935595 -0.004" rpy="1.5708 1.5708 0"/>
      <geometry>
        <mesh filename="assets/l_ankle.stl"/>
      </geometry>
    </collision>
  </link>
  <!-- Link l_foot_assembly_2 -->
  <link name="l_foot_assembly_2">
    <inertial>
      <origin xyz="-2.1647e-07 0.0064986 -0.00996008" rpy="0 0 0"/>
      <mass value="0.282308"/>
      <inertia ixx="0.000678573" ixy="1.86655e-10" ixz="-3.27534e-09" iyy="0.000739455" iyz="-2.40954e-05" izz="0.000104866"/>
    </inertial>
    <!-- Part frame_13 -->
    <visual>
      <origin xyz="-2.77556e-17 0 -0.01" rpy="1.5708 1.04083e-16 9.50455e-16"/>
      <geometry>
        <mesh filename="assets/frame.stl"/>
      </geometry>
      <material name="frame_13_material">
        <color rgba="0.917647 0.917647 0.917647 1"/>
      </material>
    </visual>
    <collision>
      <origin xyz="-2.77556e-17 0 -0.01" rpy="1.5708 1.04083e-16 9.50455e-16"/>
      <geometry>
        <mesh filename="assets/frame.stl"/>
      </geometry>
    </collision>
    <!-- Part l_foot_2 -->
    <visual>
      <origin xyz="-1.154e-08 0.0064987 -0.00995996" rpy="1.5708 -2.36713e-33 0"/>
      <geometry>
        <mesh filename="assets/l_foot.stl"/>
      </geometry>
      <material name="l_foot_2_material">
        <color rgba="0.615686 0.811765 0.929412 1"/>
      </material>
    </visual>
    <collision>
      <origin xyz="-1.154e-08 0.0064987 -0.00995996" rpy="1.5708 -2.36713e-33 0"/>
      <geometry>
        <mesh filename="assets/l_foot.stl"/>
      </geometry>
    </collision>
  </link>
  <!-- Joint from l_ankle_assembly_2 to l_foot_assembly_2 -->
  <joint name="right_ankle_roll_joint" type="revolute">
    <origin xyz="0.0195 0.015 -0.004" rpy="6.66134e-16 1.5708 0"/>
    <parent link="l_ankle_assembly_2"/>
    <child link="l_foot_assembly_2"/>
    <axis xyz="0 0 1"/>
    <limit effort="10" velocity="10" lower="-0.349066" upper="0.349066"/>
  </joint>
  <!-- Joint from r_tibia_assembly to l_ankle_assembly_2 -->
  <joint name="right_ankle_pitch_joint" type="revolute">
    <origin xyz="0.0015 0.38 0.0291" rpy="8.32667e-17 7.24451e-30 -2.17307e-29"/>
    <parent link="r_tibia_assembly"/>
    <child link="l_ankle_assembly_2"/>
    <axis xyz="0 0 1"/>
    <limit effort="10" velocity="10" lower="-0.785398" upper="0.523599"/>
  </joint>
  <!-- Joint from r_lower_femur_assembly to r_tibia_assembly -->
  <joint name="right_knee_joint" type="revolute">
    <origin xyz="0.025 7.40781e-17 -0.203" rpy="-1.5708 2.28092e-29 1.5708"/>
    <parent link="r_lower_femur_assembly"/>
    <child link="r_tibia_assembly"/>
    <axis xyz="0 0 1"/>
    <limit effort="10" velocity="10" lower="-0.174533" upper="2.35619"/>
  </joint>
  <!-- Joint from r_upper_femur_assemby to r_lower_femur_assembly -->
  <joint name="right_hip_yaw_joint" type="revolute">
    <origin xyz="-1.66533e-16 -0.145 0.035" rpy="-1.5708 6.63672e-29 3.22255e-16"/>
    <parent link="r_upper_femur_assemby"/>
    <child link="r_lower_femur_assembly"/>
    <axis xyz="0 0 1"/>
    <limit effort="10" velocity="10" lower="-1.5708" upper="1.5708"/>
  </joint>
  <!-- Joint from r_hip_assembly to r_upper_femur_assemby -->
  <joint name="right_hip_roll_joint" type="revolute">
    <origin xyz="0.035 0 -0.1" rpy="3.14159 1.5708 0"/>
    <parent link="r_hip_assembly"/>
    <child link="r_upper_femur_assemby"/>
    <axis xyz="0 0 1"/>
    <limit effort="10" velocity="10" lower="-0.523599" upper="1.5708"/>
  </joint>
  <!-- Joint from pelvis_assembly to r_hip_assembly -->
  <joint name="right_hip_pitch_joint" type="revolute">
    <origin xyz="0.103 -1.16552e-17 -0.127" rpy="-1.5708 -3.69779e-32 1.5708"/>
    <parent link="pelvis_assembly"/>
    <child link="r_hip_assembly"/>
    <axis xyz="0 0 1"/>
    <limit effort="10" velocity="10" lower="-2.53073" upper="1.5708"/>
  </joint>
  <!-- Joint from base to pelvis_assembly -->
  <joint name="waist_yaw_joint" type="revolute">
    <origin xyz="0.000721188 0.00013182 -0.325769" rpy="6.12323e-17 -6.12323e-17 -7.54747e-49"/>
    <parent link="base"/>
    <child link="pelvis_assembly"/>
    <axis xyz="0 0 1"/>
    <limit effort="10" velocity="10" lower="-1.5708" upper="1.5708"/>
  </joint>
  <!-- Link l_shoulder_assembly -->
  <link name="l_shoulder_assembly">
    <inertial>
      <origin xyz="-0.0185943 -1.84132e-16 -0.0493022" rpy="0 0 0"/>
      <mass value="0.928396"/>
      <inertia ixx="0.00188831" ixy="3.8581e-20" ixz="-0.000134376" iyy="0.00201564" iyz="1.3603e-19" izz="0.0015564"/>
    </inertial>
    <!-- Part frame_14 -->
    <visual>
      <origin xyz="-1.16552e-18 -2.22045e-16 0" rpy="-1.5708 -1.5708 0"/>
      <geometry>
        <mesh filename="assets/frame.stl"/>
      </geometry>
      <material name="frame_14_material">
        <color rgba="0.917647 0.917647 0.917647 1"/>
      </material>
    </visual>
    <collision>
      <origin xyz="-1.16552e-18 -2.22045e-16 0" rpy="-1.5708 -1.5708 0"/>
      <geometry>
        <mesh filename="assets/frame.stl"/>
      </geometry>
    </collision>
    <!-- Part l_shoulder -->
    <visual>
      <origin xyz="-0.0185943 -1.94289e-16 -0.0493022" rpy="-1.5708 -1.5708 0"/>
      <geometry>
        <mesh filename="assets/l_shoulder.stl"/>
      </geometry>
      <material name="l_shoulder_material">
        <color rgba="0.615686 0.811765 0.929412 1"/>
      </material>
    </visual>
    <collision>
      <origin xyz="-0.0185943 -1.94289e-16 -0.0493022" rpy="-1.5708 -1.5708 0"/>
      <geometry>
        <mesh filename="assets/l_shoulder.stl"/>
      </geometry>
    </collision>
  </link>
  <!-- Link l_upper_arm_assembly -->
  <link name="l_upper_arm_assembly">
    <inertial>
      <origin xyz="-3.43737e-07 -0.0849026 0.0221296" rpy="0 0 0"/>
      <mass value="1.1133"/>
      <inertia ixx="0.00383878" ixy="3.74641e-09" ixz="-1.61493e-08" iyy="0.00238492" iyz="0.000499003" izz="0.00373704"/>
    </inertial>
    <!-- Part frame_15 -->
    <visual>
      <origin xyz="0 0 0" rpy="-1.5708 -5.20001e-33 -9.24446e-33"/>
      <geometry>
        <mesh filename="assets/frame.stl"/>
      </geometry>
      <material name="frame_15_material">
        <color rgba="0.917647 0.917647 0.917647 1"/>
      </material>
    </visual>
    <collision>
      <origin xyz="0 0 0" rpy="-1.5708 -5.20001e-33 -9.24446e-33"/>
      <geometry>
        <mesh filename="assets/frame.stl"/>
      </geometry>
    </collision>
    <!-- Part l_upper_arm -->
    <visual>
      <origin xyz="2.3715e-08 -0.0849023 0.0221291" rpy="-1.5708 -5.20001e-33 -9.24446e-33"/>
      <geometry>
        <mesh filename="assets/l_upper_arm.stl"/>
      </geometry>
      <material name="l_upper_arm_material">
        <color rgba="0.615686 0.811765 0.929412 1"/>
      </material>
    </visual>
    <collision>
      <origin xyz="2.3715e-08 -0.0849023 0.0221291" rpy="-1.5708 -5.20001e-33 -9.24446e-33"/>
      <geometry>
        <mesh filename="assets/l_upper_arm.stl"/>
      </geometry>
    </collision>
  </link>
  <!-- Link l_elbow_assembly -->
  <link name="l_elbow_assembly">
    <inertial>
      <origin xyz="0.00799675 -1.8573e-08 -0.0435193" rpy="0 0 0"/>
      <mass value="0.736611"/>
      <inertia ixx="0.0012452" ixy="4.76803e-10" ixz="0.000185437" iyy="0.00127446" iyz="1.70636e-10" izz="0.000933148"/>
    </inertial>
    <!-- Part frame_16 -->
    <visual>
      <origin xyz="6.27276e-15 -1.0842e-19 0" rpy="-5.55112e-17 4.16334e-17 1.28023e-15"/>
      <geometry>
        <mesh filename="assets/frame.stl"/>
      </geometry>
      <material name="frame_16_material">
        <color rgba="0.917647 0.917647 0.917647 1"/>
      </material>
    </visual>
    <collision>
      <origin xyz="6.27276e-15 -1.0842e-19 0" rpy="-5.55112e-17 4.16334e-17 1.28023e-15"/>
      <geometry>
        <mesh filename="assets/frame.stl"/>
      </geometry>
    </collision>
    <!-- Part l_elbow -->
    <visual>
      <origin xyz="0.00799674 -7.5627e-09 -0.0435193" rpy="6.16298e-33 -3.08149e-33 1.61778e-32"/>
      <geometry>
        <mesh filename="assets/l_elbow.stl"/>
      </geometry>
      <material name="l_elbow_material">
        <color rgba="0.615686 0.811765 0.929412 1"/>
      </material>
    </visual>
    <collision>
      <origin xyz="0.00799674 -7.5627e-09 -0.0435193" rpy="6.16298e-33 -3.08149e-33 1.61778e-32"/>
      <geometry>
        <mesh filename="assets/l_elbow.stl"/>
      </geometry>
    </collision>
  </link>
  <!-- Link l_upper_forearm_assembly -->
  <link name="l_upper_forearm_assembly">
    <inertial>
      <origin xyz="-5.82407e-09 -0.0592136 0.0187478" rpy="0 0 0"/>
      <mass value="0.728397"/>
      <inertia ixx="0.00170969" ixy="1.46324e-10" ixz="2.53669e-09" iyy="0.00116568" iyz="0.000269664" izz="0.00154551"/>
    </inertial>
    <!-- Part frame_17 -->
    <visual>
      <origin xyz="3.46945e-18 1.38778e-17 0" rpy="-1.5708 -1.5708 0"/>
      <geometry>
        <mesh filename="assets/frame.stl"/>
      </geometry>
      <material name="frame_17_material">
        <color rgba="0.917647 0.917647 0.917647 1"/>
      </material>
    </visual>
    <collision>
      <origin xyz="3.46945e-18 1.38778e-17 0" rpy="-1.5708 -1.5708 0"/>
      <geometry>
        <mesh filename="assets/frame.stl"/>
      </geometry>
    </collision>
    <!-- Part l_upper_forearm -->
    <visual>
      <origin xyz="-1.08565e-08 -0.0592137 0.0187478" rpy="-1.5708 -1.5708 0"/>
      <geometry>
        <mesh filename="assets/l_upper_forearm.stl"/>
      </geometry>
      <material name="l_upper_forearm_material">
        <color rgba="0.615686 0.811765 0.929412 1"/>
      </material>
    </visual>
    <collision>
      <origin xyz="-1.08565e-08 -0.0592137 0.0187478" rpy="-1.5708 -1.5708 0"/>
      <geometry>
        <mesh filename="assets/l_upper_forearm.stl"/>
      </geometry>
    </collision>
  </link>
  <!-- Link l_lower_forearm_assembly -->
  <link name="l_lower_forearm_assembly">
    <inertial>
      <origin xyz="0.00212721 1.09486e-07 -0.0228757" rpy="0 0 0"/>
      <mass value="0.209186"/>
      <inertia ixx="0.000199002" ixy="9.13221e-10" ixz="6.50777e-06" iyy="0.000260365" iyz="4.87615e-10" izz="0.0002757"/>
    </inertial>
    <!-- Part frame_18 -->
    <visual>
      <origin xyz="0 -1.0842e-19 0" rpy="9.86076e-32 1.05097e-45 4.31408e-32"/>
      <geometry>
        <mesh filename="assets/frame.stl"/>
      </geometry>
      <material name="frame_18_material">
        <color rgba="0.917647 0.917647 0.917647 1"/>
      </material>
    </visual>
    <collision>
      <origin xyz="0 -1.0842e-19 0" rpy="9.86076e-32 1.05097e-45 4.31408e-32"/>
      <geometry>
        <mesh filename="assets/frame.stl"/>
      </geometry>
    </collision>
    <!-- Part l_lower_forearm -->
    <visual>
      <origin xyz="0.0021283 -6.79095e-09 -0.0228754" rpy="4.93038e-32 1.05097e-45 -5.54668e-32"/>
      <geometry>
        <mesh filename="assets/l_lower_forearm.stl"/>
      </geometry>
      <material name="l_lower_forearm_material">
        <color rgba="0.615686 0.811765 0.929412 1"/>
      </material>
    </visual>
    <collision>
      <origin xyz="0.0021283 -6.79095e-09 -0.0228754" rpy="4.93038e-32 1.05097e-45 -5.54668e-32"/>
      <geometry>
        <mesh filename="assets/l_lower_forearm.stl"/>
      </geometry>
    </collision>
  </link>
  <!-- Link l_forearm_linkage_assembly -->
  <link name="l_forearm_linkage_assembly">
    <inertial>
      <origin xyz="-2.17029e-18 0.0375 -0.03" rpy="0 0 0"/>
      <mass value="0.549558"/>
      <inertia ixx="0.000863537" ixy="-2.71026e-35" ixz="-2.76742e-34" iyy="0.00031383" iyz="-1.16048e-35" izz="0.000863537"/>
    </inertial>
    <!-- Part frame_19 -->
    <visual>
      <origin xyz="1.0842e-19 -2.77556e-17 -5.55112e-17" rpy="1.5708 1.5708 0"/>
      <geometry>
        <mesh filename="assets/frame.stl"/>
      </geometry>
      <material name="frame_19_material">
        <color rgba="0.917647 0.917647 0.917647 1"/>
      </material>
    </visual>
    <collision>
      <origin xyz="1.0842e-19 -2.77556e-17 -5.55112e-17" rpy="1.5708 1.5708 0"/>
      <geometry>
        <mesh filename="assets/frame.stl"/>
      </geometry>
    </collision>
    <!-- Part l_forearm_linkage -->
    <visual>
      <origin xyz="-9.75782e-19 0.0375 -0.03" rpy="1.5708 1.5708 0"/>
      <geometry>
        <mesh filename="assets/l_forearm_linkage.stl"/>
      </geometry>
      <material name="l_forearm_linkage_material">
        <color rgba="0.615686 0.811765 0.929412 1"/>
      </material>
    </visual>
    <collision>
      <origin xyz="-9.75782e-19 0.0375 -0.03" rpy="1.5708 1.5708 0"/>
      <geometry>
        <mesh filename="assets/l_forearm_linkage.stl"/>
      </geometry>
    </collision>
  </link>
  <!-- Link l_wrist_assembly -->
  <link name="l_wrist_assembly">
    <inertial>
      <origin xyz="-0.000663069 -0.0190316 0.0332967" rpy="0 0 0"/>
      <mass value="0.222303"/>
      <inertia ixx="0.000337905" ixy="-9.78226e-06" ixz="3.97497e-07" iyy="0.000280065" iyz="-3.86151e-06" izz="0.000280541"/>
    </inertial>
    <!-- Part frame_20 -->
    <visual>
      <origin xyz="0 5.55112e-17 0" rpy="-1.5708 1.48168e-31 7.39557e-32"/>
      <geometry>
        <mesh filename="assets/frame.stl"/>
      </geometry>
      <material name="frame_20_material">
        <color rgba="0.917647 0.917647 0.917647 1"/>
      </material>
    </visual>
    <collision>
      <origin xyz="0 5.55112e-17 0" rpy="-1.5708 1.48168e-31 7.39557e-32"/>
      <geometry>
        <mesh filename="assets/frame.stl"/>
      </geometry>
    </collision>
    <!-- Part l_wrist -->
    <visual>
      <origin xyz="-0.000662978 -0.0190318 0.0332978" rpy="-1.5708 -6.12323e-17 -1.08382e-45"/>
      <geometry>
        <mesh filename="assets/l_wrist.stl"/>
      </geometry>
      <material name="l_wrist_material">
        <color rgba="1 0 0 1"/>
      </material>
    </visual>
    <collision>
      <origin xyz="-0.000662978 -0.0190318 0.0332978" rpy="-1.5708 -6.12323e-17 -1.08382e-45"/>
      <geometry>
        <mesh filename="assets/l_wrist.stl"/>
      </geometry>
    </collision>
  </link>
  <!-- Joint from l_forearm_linkage_assembly to l_wrist_assembly -->
  <joint name="left_wrist_linkage_roll_joint" type="revolute">
    <origin xyz="0.03 0.075 -0.03" rpy="-3.14159 1.5708 0"/>
    <parent link="l_forearm_linkage_assembly"/>
    <child link="l_wrist_assembly"/>
    <axis xyz="0 0 1"/>
    <limit effort="10" velocity="10" lower="-2.61799" upper="2.61799"/>
  </joint>
  <!-- Joint from l_lower_forearm_assembly to l_forearm_linkage_assembly -->
  <joint name="left_wrist_linkage_pitch_joint" type="revolute">
    <origin xyz="-0.031 2.60209e-18 -0.0375" rpy="-1.5708 -4.93038e-32 1.5708"/>
    <parent link="l_lower_forearm_assembly"/>
    <child link="l_forearm_linkage_assembly"/>
    <axis xyz="0 0 1"/>
    <limit effort="10" velocity="10" lower="-1.5708" upper="1.5708"/>
  </joint>
  <!-- Joint from l_upper_forearm_assembly to l_lower_forearm_assembly -->
  <joint name="left_wrist_linkage_yaw_joint" type="revolute">
    <origin xyz="-2.1684e-18 -0.125 0.025" rpy="-1.5708 -1.5708 0"/>
    <parent link="l_upper_forearm_assembly"/>
    <child link="l_lower_forearm_assembly"/>
    <axis xyz="0 0 1"/>
    <limit effort="10" velocity="10" lower="-2.61799" upper="2.61799"/>
  </joint>
  <!-- Joint from l_elbow_assembly to l_upper_forearm_assembly -->
  <joint name="left_elbow_joint" type="revolute">
    <origin xyz="-0.025 -1.95156e-18 -0.075" rpy="1.5708 3.33067e-16 1.5708"/>
    <parent link="l_elbow_assembly"/>
    <child link="l_upper_forearm_assembly"/>
    <axis xyz="0 0 1"/>
    <limit effort="10" velocity="10" lower="-0.349066" upper="1.5708"/>
  </joint>
  <!-- Joint from l_upper_arm_assembly to l_elbow_assembly -->
  <joint name="left_shoulder_yaw_joint" type="revolute">
    <origin xyz="1.11022e-16 -0.165 0.0275" rpy="-1.5708 -8.10116e-16 3.95517e-16"/>
    <parent link="l_upper_arm_assembly"/>
    <child link="l_elbow_assembly"/>
    <axis xyz="0 0 1"/>
    <limit effort="10" velocity="10" lower="-2.61799" upper="2.61799"/>
  </joint>
  <!-- Joint from l_shoulder_assembly to l_upper_arm_assembly -->
  <joint name="left_shoulder_roll_joint" type="revolute">
    <origin xyz="0.028 -1.94289e-16 -0.078" rpy="2.77556e-17 -1.5708 0"/>
    <parent link="l_shoulder_assembly"/>
    <child link="l_upper_arm_assembly"/>
    <axis xyz="0 0 1"/>
    <limit effort="10" velocity="10" lower="-3.14159" upper="0"/>
  </joint>
  <!-- Joint from base to l_shoulder_assembly -->
  <joint name="left_shoulder_pitch_joint" type="revolute">
    <origin xyz="-0.224279 0.00013182 0.197231" rpy="1.5708 -0 1.5708"/>
    <parent link="base"/>
    <child link="l_shoulder_assembly"/>
    <axis xyz="0 0 1"/>
    <limit effort="10" velocity="10" lower="-1.5708" upper="1.5708"/>
  </joint>
  <!-- Link r_shoulder_assembly -->
  <link name="r_shoulder_assembly">
    <inertial>
      <origin xyz="-0.0185943 2.13669e-16 -0.0493022" rpy="0 0 0"/>
      <mass value="0.928396"/>
      <inertia ixx="0.00188831" ixy="4.92951e-27" ixz="-0.000134376" iyy="0.00201564" iyz="-2.04982e-25" izz="0.0015564"/>
    </inertial>
    <!-- Part frame_21 -->
    <visual>
      <origin xyz="-1.74285e-17 2.22045e-16 2.77556e-17" rpy="1.5708 1.5708 0"/>
      <geometry>
        <mesh filename="assets/frame.stl"/>
      </geometry>
      <material name="frame_21_material">
        <color rgba="0.917647 0.917647 0.917647 1"/>
      </material>
    </visual>
    <collision>
      <origin xyz="-1.74285e-17 2.22045e-16 2.77556e-17" rpy="1.5708 1.5708 0"/>
      <geometry>
        <mesh filename="assets/frame.stl"/>
      </geometry>
    </collision>
    <!-- Part r_shoulder -->
    <visual>
      <origin xyz="-0.0185943 4.44089e-16 -0.0493022" rpy="1.5708 1.5708 0"/>
      <geometry>
        <mesh filename="assets/r_shoulder.stl"/>
      </geometry>
      <material name="r_shoulder_material">
        <color rgba="0.615686 0.811765 0.929412 1"/>
      </material>
    </visual>
    <collision>
      <origin xyz="-0.0185943 4.44089e-16 -0.0493022" rpy="1.5708 1.5708 0"/>
      <geometry>
        <mesh filename="assets/r_shoulder.stl"/>
      </geometry>
    </collision>
  </link>
  <!-- Link r_upper_arm_assembly -->
  <link name="r_upper_arm_assembly">
    <inertial>
      <origin xyz="-9.3082e-08 -0.0849026 0.0221297" rpy="0 0 0"/>
      <mass value="1.1133"/>
      <inertia ixx="0.00383875" ixy="4.7399e-09" ixz="-8.61473e-09" iyy="0.00238492" iyz="0.000498994" izz="0.00373706"/>
    </inertial>
    <!-- Part frame_22 -->
    <visual>
      <origin xyz="5.55112e-17 -2.77556e-17 0" rpy="-1.5708 1.26957e-30 0"/>
      <geometry>
        <mesh filename="assets/frame.stl"/>
      </geometry>
      <material name="frame_22_material">
        <color rgba="0.917647 0.917647 0.917647 1"/>
      </material>
    </visual>
    <collision>
      <origin xyz="5.55112e-17 -2.77556e-17 0" rpy="-1.5708 1.26957e-30 0"/>
      <geometry>
        <mesh filename="assets/frame.stl"/>
      </geometry>
    </collision>
    <!-- Part r_upper_arm -->
    <visual>
      <origin xyz="-9.88939e-08 -0.0849026 0.0221297" rpy="-1.5708 2.12587e-53 0"/>
      <geometry>
        <mesh filename="assets/r_upper_arm.stl"/>
      </geometry>
      <material name="r_upper_arm_material">
        <color rgba="0.615686 0.811765 0.929412 1"/>
      </material>
    </visual>
    <collision>
      <origin xyz="-9.88939e-08 -0.0849026 0.0221297" rpy="-1.5708 2.12587e-53 0"/>
      <geometry>
        <mesh filename="assets/r_upper_arm.stl"/>
      </geometry>
    </collision>
  </link>
  <!-- Link r_elbow_assembly -->
  <link name="r_elbow_assembly">
    <inertial>
      <origin xyz="-0.00799675 -1.944e-08 -0.0435193" rpy="0 0 0"/>
      <mass value="0.736611"/>
      <inertia ixx="0.0012452" ixy="-4.55573e-10" ixz="-0.000185437" iyy="0.00127447" iyz="1.68986e-10" izz="0.00093316"/>
    </inertial>
    <!-- Part frame_23 -->
    <visual>
      <origin xyz="1.11022e-16 -2.23346e-17 6.93889e-18" rpy="5.55112e-16 -6.27803e-16 -6.02443e-17"/>
      <geometry>
        <mesh filename="assets/frame.stl"/>
      </geometry>
      <material name="frame_23_material">
        <color rgba="0.917647 0.917647 0.917647 1"/>
      </material>
    </visual>
    <collision>
      <origin xyz="1.11022e-16 -2.23346e-17 6.93889e-18" rpy="5.55112e-16 -6.27803e-16 -6.02443e-17"/>
      <geometry>
        <mesh filename="assets/frame.stl"/>
      </geometry>
    </collision>
    <!-- Part r_elbow -->
    <visual>
      <origin xyz="-0.00799674 -7.28961e-09 -0.0435193" rpy="0 -0 -1.18558e-31"/>
      <geometry>
        <mesh filename="assets/r_elbow.stl"/>
      </geometry>
      <material name="r_elbow_material">
        <color rgba="0.615686 0.811765 0.929412 1"/>
      </material>
    </visual>
    <collision>
      <origin xyz="-0.00799674 -7.28961e-09 -0.0435193" rpy="0 -0 -1.18558e-31"/>
      <geometry>
        <mesh filename="assets/r_elbow.stl"/>
      </geometry>
    </collision>
  </link>
  <!-- Link r_upper_forearm_assembly -->
  <link name="r_upper_forearm_assembly">
    <inertial>
      <origin xyz="-6.87143e-09 0.0592136 0.0187478" rpy="0 0 0"/>
      <mass value="0.728398"/>
      <inertia ixx="0.00170969" ixy="-1.72305e-10" ixz="1.24621e-09" iyy="0.00116568" iyz="-0.000269664" izz="0.00154551"/>
    </inertial>
    <!-- Part frame_24 -->
    <visual>
      <origin xyz="-4.22839e-18 -6.93889e-18 -5.55112e-17" rpy="1.5708 1.5708 0"/>
      <geometry>
        <mesh filename="assets/frame.stl"/>
      </geometry>
      <material name="frame_24_material">
        <color rgba="0.917647 0.917647 0.917647 1"/>
      </material>
    </visual>
    <collision>
      <origin xyz="-4.22839e-18 -6.93889e-18 -5.55112e-17" rpy="1.5708 1.5708 0"/>
      <geometry>
        <mesh filename="assets/frame.stl"/>
      </geometry>
    </collision>
    <!-- Part r_upper_forearm -->
    <visual>
      <origin xyz="-9.42553e-09 0.0592137 0.0187478" rpy="1.5708 1.5708 0"/>
      <geometry>
        <mesh filename="assets/r_upper_forearm.stl"/>
      </geometry>
      <material name="r_upper_forearm_material">
        <color rgba="0.615686 0.811765 0.929412 1"/>
      </material>
    </visual>
    <collision>
      <origin xyz="-9.42553e-09 0.0592137 0.0187478" rpy="1.5708 1.5708 0"/>
      <geometry>
        <mesh filename="assets/r_upper_forearm.stl"/>
      </geometry>
    </collision>
  </link>
  <!-- Link r_lower_forearm_assembly -->
  <link name="r_lower_forearm_assembly">
    <inertial>
      <origin xyz="-0.00212722 -5.20387e-08 -0.0228757" rpy="0 0 0"/>
      <mass value="0.209186"/>
      <inertia ixx="0.000199002" ixy="5.06889e-11" ixz="-6.50779e-06" iyy="0.000260364" iyz="-5.78131e-10" izz="0.0002757"/>
    </inertial>
    <!-- Part frame_25 -->
    <visual>
      <origin xyz="0 -1.0842e-19 0" rpy="-2.22045e-16 1.2837e-16 4.25007e-17"/>
      <geometry>
        <mesh filename="assets/frame.stl"/>
      </geometry>
      <material name="frame_25_material">
        <color rgba="0.917647 0.917647 0.917647 1"/>
      </material>
    </visual>
    <collision>
      <origin xyz="0 -1.0842e-19 0" rpy="-2.22045e-16 1.2837e-16 4.25007e-17"/>
      <geometry>
        <mesh filename="assets/frame.stl"/>
      </geometry>
    </collision>
    <!-- Part r_lower_forearm -->
    <visual>
      <origin xyz="-0.0021283 -6.79095e-09 -0.0228754" rpy="-4.74463e-31 -1.29581e-30 1.77646e-31"/>
      <geometry>
        <mesh filename="assets/r_lower_forearm.stl"/>
      </geometry>
      <material name="r_lower_forearm_material">
        <color rgba="0.615686 0.811765 0.929412 1"/>
      </material>
    </visual>
    <collision>
      <origin xyz="-0.0021283 -6.79095e-09 -0.0228754" rpy="-4.74463e-31 -1.29581e-30 1.77646e-31"/>
      <geometry>
        <mesh filename="assets/r_lower_forearm.stl"/>
      </geometry>
    </collision>
  </link>
  <!-- Link r_forearm_linkage_assembly -->
  <link name="r_forearm_linkage_assembly">
    <inertial>
      <origin xyz="-2.27153e-18 -0.0375 -0.03" rpy="0 0 0"/>
      <mass value="0.549558"/>
      <inertia ixx="0.000863537" ixy="9.3491e-34" ixz="5.96366e-35" iyy="0.00031383" iyz="1.31934e-34" izz="0.000863537"/>
    </inertial>
    <!-- Part frame_26 -->
    <visual>
      <origin xyz="-2.1684e-19 -2.77556e-17 0" rpy="-1.5708 -1.5708 0"/>
      <geometry>
        <mesh filename="assets/frame.stl"/>
      </geometry>
      <material name="frame_26_material">
        <color rgba="0.917647 0.917647 0.917647 1"/>
      </material>
    </visual>
    <collision>
      <origin xyz="-2.1684e-19 -2.77556e-17 0" rpy="-1.5708 -1.5708 0"/>
      <geometry>
        <mesh filename="assets/frame.stl"/>
      </geometry>
    </collision>
    <!-- Part r_forearm_linkage -->
    <visual>
      <origin xyz="-1.19262e-18 -0.0375 -0.03" rpy="-1.5708 -1.5708 0"/>
      <geometry>
        <mesh filename="assets/r_forearm_linkage.stl"/>
      </geometry>
      <material name="r_forearm_linkage_material">
        <color rgba="0.615686 0.811765 0.929412 1"/>
      </material>
    </visual>
    <collision>
      <origin xyz="-1.19262e-18 -0.0375 -0.03" rpy="-1.5708 -1.5708 0"/>
      <geometry>
        <mesh filename="assets/r_forearm_linkage.stl"/>
      </geometry>
    </collision>
  </link>
  <!-- Link r_wrist_assembly -->
  <link name="r_wrist_assembly">
    <inertial>
      <origin xyz="0.000662917 -0.0190316 0.0332967" rpy="0 0 0"/>
      <mass value="0.222303"/>
      <inertia ixx="0.000337905" ixy="9.78318e-06" ixz="-3.98466e-07" iyy="0.000280065" iyz="-3.86152e-06" izz="0.000280541"/>
    </inertial>
    <!-- Part frame_27 -->
    <visual>
      <origin xyz="0 5.55112e-17 3.46945e-18" rpy="-1.5708 -2.06702e-31 -1.93076e-30"/>
      <geometry>
        <mesh filename="assets/frame.stl"/>
      </geometry>
      <material name="frame_27_material">
        <color rgba="0.917647 0.917647 0.917647 1"/>
      </material>
    </visual>
    <collision>
      <origin xyz="0 5.55112e-17 3.46945e-18" rpy="-1.5708 -2.06702e-31 -1.93076e-30"/>
      <geometry>
        <mesh filename="assets/frame.stl"/>
      </geometry>
    </collision>
    <!-- Part r_wrist -->
    <visual>
      <origin xyz="0.000662978 -0.0190318 0.0332978" rpy="-1.5708 6.12323e-17 -8.24165e-30"/>
      <geometry>
        <mesh filename="assets/r_wrist.stl"/>
      </geometry>
      <material name="r_wrist_material">
        <color rgba="1 0 0 1"/>
      </material>
    </visual>
    <collision>
      <origin xyz="0.000662978 -0.0190318 0.0332978" rpy="-1.5708 6.12323e-17 -8.24165e-30"/>
      <geometry>
        <mesh filename="assets/r_wrist.stl"/>
      </geometry>
    </collision>
  </link>
  <!-- Joint from r_forearm_linkage_assembly to r_wrist_assembly -->
  <joint name="right_wrist_linkage_roll_joint" type="revolute">
    <origin xyz="0.03 -0.075 -0.03" rpy="9.25186e-17 -1.5708 0"/>
    <parent link="r_forearm_linkage_assembly"/>
    <child link="r_wrist_assembly"/>
    <axis xyz="0 0 1"/>
    <limit effort="10" velocity="10" lower="-2.61799" upper="2.61799"/>
  </joint>
  <!-- Joint from r_lower_forearm_assembly to r_forearm_linkage_assembly -->
  <joint name="right_wrist_linkage_pitch_joint" type="revolute">
    <origin xyz="0.031 2.71051e-18 -0.0375" rpy="1.5708 3.67194e-14 1.5708"/>
    <parent link="r_lower_forearm_assembly"/>
    <child link="r_forearm_linkage_assembly"/>
    <axis xyz="0 0 1"/>
    <limit effort="10" velocity="10" lower="-1.5708" upper="1.5708"/>
  </joint>
  <!-- Joint from r_upper_forearm_assembly to r_lower_forearm_assembly -->
  <joint name="right_wrist_linkage_yaw_joint" type="revolute">
    <origin xyz="6.70254e-16 0.125 0.025" rpy="1.5708 1.5708 0"/>
    <parent link="r_upper_forearm_assembly"/>
    <child link="r_lower_forearm_assembly"/>
    <axis xyz="0 0 1"/>
    <limit effort="10" velocity="10" lower="-2.61799" upper="2.61799"/>
  </joint>
  <!-- Joint from r_elbow_assembly to r_upper_forearm_assembly -->
  <joint name="right_elbow_joint" type="revolute">
    <origin xyz="0.025 2.15648e-16 -0.075" rpy="-1.5708 -2.27596e-15 1.5708"/>
    <parent link="r_elbow_assembly"/>
    <child link="r_upper_forearm_assembly"/>
    <axis xyz="0 0 1"/>
    <limit effort="10" velocity="10" lower="-0.349066" upper="1.5708"/>
  </joint>
  <!-- Joint from r_upper_arm_assembly to r_elbow_assembly -->
  <joint name="right_shoulder_yaw_joint" type="revolute">
    <origin xyz="-5.55112e-17 -0.165 0.0275" rpy="-1.5708 -1.70091e-15 -2.78879e-15"/>
    <parent link="r_upper_arm_assembly"/>
    <child link="r_elbow_assembly"/>
    <axis xyz="0 0 1"/>
    <limit effort="10" velocity="10" lower="-2.66454e-15" upper="2.61799"/>
  </joint>
  <!-- Joint from r_shoulder_assembly to r_upper_arm_assembly -->
  <joint name="right_shoulder_roll_joint" type="revolute">
    <origin xyz="0.028 0 -0.078" rpy="3.14159 1.5708 0"/>
    <parent link="r_shoulder_assembly"/>
    <child link="r_upper_arm_assembly"/>
    <axis xyz="0 0 1"/>
    <limit effort="10" velocity="10" lower="0" upper="3.14159"/>
  </joint>
  <!-- Joint from base to r_shoulder_assembly -->
  <joint name="right_shoulder_pitch_joint" type="revolute">
    <origin xyz="0.225721 0.00013182 0.197231" rpy="-1.5708 -0 1.5708"/>
    <parent link="base"/>
    <child link="r_shoulder_assembly"/>
    <axis xyz="0 0 1"/>
    <limit effort="10" velocity="10" lower="-1.5708" upper="1.5708"/>
  </joint>
</robot>
